<?xml version="1.0" ?>
<!-- =================================================================================== -->
<!-- |    This document was autogenerated by xacro from crex.urdf.xacro                | -->
<!-- |    EDITING THIS FILE BY HAND IS NOT RECOMMENDED                                 | -->
<!-- =================================================================================== -->
<robot name="crex">
  <!-- Convention
        ===========

        body: trunk
        legx_1: hipassembly
        legx_2: upperleg
        legx_3: lowerleg

        legx/joint1: haa
        legx/joint2: hfe
        legx/joint3: kfe
    -->
  <!-- ===================================================== -->
  <!-- ===================================================== -->
  <!-- ===================================================== -->
  <material name="aluminum">
    <color rgba="0.5 0.5 0.5 1"/>
  </material>
  <!-- Now we can start using the macros included above to define the actual Crex -->
  <!-- The first use of a macro. This one was defined in trunk.urdf.xacro above.
A macro like this will expand to a set of link and joint definitions, and to additional
Gazebo-related extensions (sensor plugins, etc). The macro takes an argument, name,
that equals "base", and uses it to generate names for its component links and joints
(e.g., base_link). The included origin block is also an argument to the macro. By convention,
the origin block defines where the component is w.r.t its parent (in this case the parent
is the world frame). For more, see http://ros.org/wiki/xacro -->
  <!-- Trunk link -->
  <link name="trunk">
    <inertial>
      <origin rpy="0.0 0.0 0.0" xyz="0.0 0.0 0.0"/>
      <mass value="9.566027101513273"/>
      <inertia ixx="0.098809" ixy="0.00078999" ixz="-0.0068300" iyy="0.2307800001208933" iyz="0.0" izz="0.265829"/>
    </inertial>
  </link>
  <!-- Joints -->
  <!-- Joint 1 -->
  <joint name="lf_haa_joint" type="revolute">
    <origin rpy="3.14159 0 0" xyz="0.32729 0.16972 -0.02722"/>
    <parent link="trunk"/>
    <child link="lf_hipassembly"/>
    <axis xyz="0 0 1"/>
    <limit effort="25.0" lower="-2.35619" upper="2.35619" velocity="3.0"/>
    <dynamics damping="0.1" friction="0"/>
    <!--safety_controller k_position="50" k_velocity="10"
                      soft_lower_limit="${(1-knee_bent_backward)*(hfe_min)*PI/180 + (knee_bent_backward)*(-hfe_max)*PI/180}"
                      soft_upper_limit="${(1-knee_bent_backward)*(hfe_max)*PI/180 + (knee_bent_backward)*(-hfe_min)*PI/180}"/-->
  </joint>
  <!-- Joint 2 -->
  <joint name="lf_hfe_joint" type="revolute">
    <origin rpy="1.570794 1.570795 0" xyz="0.0 -0.03931 0.05871"/>
    <parent link="lf_hipassembly"/>
    <child link="lf_upperleg"/>
    <axis xyz="0 0 1"/>
    <limit effort="25.0" lower="-2.95" upper="2.95" velocity="3.0"/>
    <dynamics damping="0.1" friction="0"/>
    <!--safety_controller k_position="50" k_velocity="10"
                      soft_lower_limit="${(1-knee_bent_backward)*(hfe_min)*PI/180 + (knee_bent_backward)*(-hfe_max)*PI/180}"
                      soft_upper_limit="${(1-knee_bent_backward)*(hfe_max)*PI/180 + (knee_bent_backward)*(-hfe_min)*PI/180}"/-->
  </joint>
  <!-- Joint 3 -->
  <joint name="lf_kfe_joint" type="revolute">
    <origin rpy="0.0 0.0 3.141591" xyz="0.22 0.0 0.0409"/>
    <parent link="lf_upperleg"/>
    <child link="lf_lowerleg"/>
    <axis xyz="0 0 1"/>
    <limit effort="25.0" lower="-2.95" upper="2.95" velocity="3.0"/>
    <dynamics damping="0.1" friction="0"/>
    <!--safety_controller k_position="50" k_velocity="10"
                      soft_lower_limit="${(1-knee_bent_backward)*(hfe_min)*PI/180 + (knee_bent_backward)*(-hfe_max)*PI/180}"
                      soft_upper_limit="${(1-knee_bent_backward)*(hfe_max)*PI/180 + (knee_bent_backward)*(-hfe_min)*PI/180}"/-->
  </joint>
  <!-- Joint foot -->
  <joint name="lf_foot_joint" type="fixed">
    <origin rpy="-3.141592 0.0 0.0" xyz="0.28 -0.00028 0.00674"/>
    <parent link="lf_lowerleg"/>
    <child link="lf_foot"/>
  </joint>
  <!-- Links of Peripheral Legs-->
  <!-- Link 1 -->
  <link name="lf_hipassembly">
    <inertial>
      <origin rpy="0.0 0.0 0.0" xyz="0.0 -0.0014 0.05421"/>
      <mass value="0.547"/>
      <inertia ixx="0.00158" ixy="0.0" ixz="0.0" iyy="0.00124" iyz="-0.0001" izz="0.00115"/>
    </inertial>
  </link>
  <!-- Link 2 -->
  <link name="lf_upperleg">
    <inertial>
      <origin rpy="0.0 0.0 0.0" xyz="0.195737 0.0 0.003607"/>
      <mass value="0.66"/>
      <inertia ixx="0.00181" ixy="0.0" ixz="0.00037" iyy="0.0075" iyz="0.0" izz="0.00781"/>
    </inertial>
  </link>
  <!-- Link 3 -->
  <link name="lf_lowerleg">
    <inertial>
      <origin rpy="0.0 0.0 0.0" xyz="0.08880 0.0 0.0207547"/>
      <mass value="0.721839"/>
      <inertia ixx="0.00384" ixy="0.0" ixz="0.0" iyy="0.00235" iyz="0.0" izz="0.00472"/>
    </inertial>
  </link>
  <!-- Link foot -->
  <link name="lf_foot">
    <!--                        <inertial>
                          <origin xyz="0 0 0" rpy="0 0 0"/>
                          <mass value="1"/>
                          <inertia ixx="1.0" ixy="0.0" ixz="0.0" iyy="1.0" iyz="0.0" izz="1.0"/>
                        </inertial>-->
  </link>
  <!--//////////////////////////////////////////////////////////////////////////////////-->
  <!-- Hip assembly -->
  <!-- Joints -->
  <!-- Joint 1 -->
  <joint name="rf_haa_joint" type="revolute">
    <origin rpy="0 3.141592 0" xyz="0.32729 -0.16972 -0.02722"/>
    <parent link="trunk"/>
    <child link="rf_hipassembly"/>
    <axis xyz="0 0 1"/>
    <limit effort="25.0" lower="-2.35619" upper="2.35619" velocity="3.0"/>
    <dynamics damping="0.1" friction="0"/>
    <!--safety_controller k_position="50" k_velocity="10"
                      soft_lower_limit="${(1-knee_bent_backward)*(hfe_min)*PI/180 + (knee_bent_backward)*(-hfe_max)*PI/180}"
                      soft_upper_limit="${(1-knee_bent_backward)*(hfe_max)*PI/180 + (knee_bent_backward)*(-hfe_min)*PI/180}"/-->
  </joint>
  <!-- Joint 2 -->
  <joint name="rf_hfe_joint" type="revolute">
    <origin rpy="1.570794 1.570795 0" xyz="0.0 -0.03931 0.05871"/>
    <parent link="rf_hipassembly"/>
    <child link="rf_upperleg"/>
    <axis xyz="0 0 1"/>
    <limit effort="25.0" lower="-2.95" upper="2.95" velocity="3.0"/>
    <dynamics damping="0.1" friction="0"/>
    <!--safety_controller k_position="50" k_velocity="10"
                      soft_lower_limit="${(1-knee_bent_backward)*(hfe_min)*PI/180 + (knee_bent_backward)*(-hfe_max)*PI/180}"
                      soft_upper_limit="${(1-knee_bent_backward)*(hfe_max)*PI/180 + (knee_bent_backward)*(-hfe_min)*PI/180}"/-->
  </joint>
  <!-- Joint 3 -->
  <joint name="rf_kfe_joint" type="revolute">
    <origin rpy="0.0 0.0 3.141591" xyz="0.22 0.0 0.0409"/>
    <parent link="rf_upperleg"/>
    <child link="rf_lowerleg"/>
    <axis xyz="0 0 1"/>
    <limit effort="25.0" lower="-2.95" upper="2.95" velocity="3.0"/>
    <dynamics damping="0.1" friction="0"/>
    <!--safety_controller k_position="50" k_velocity="10"
                      soft_lower_limit="${(1-knee_bent_backward)*(hfe_min)*PI/180 + (knee_bent_backward)*(-hfe_max)*PI/180}"
                      soft_upper_limit="${(1-knee_bent_backward)*(hfe_max)*PI/180 + (knee_bent_backward)*(-hfe_min)*PI/180}"/-->
  </joint>
  <!-- Joint foot -->
  <joint name="rf_foot_joint" type="fixed">
    <origin rpy="-3.141592 0.0 0.0" xyz="0.28 -0.00028 0.00674"/>
    <parent link="rf_lowerleg"/>
    <child link="rf_foot"/>
  </joint>
  <!-- Links of Peripheral Legs-->
  <!-- Link 1 -->
  <link name="rf_hipassembly">
    <inertial>
      <origin rpy="0.0 0.0 0.0" xyz="0.0 -0.0014 0.05421"/>
      <mass value="0.547"/>
      <inertia ixx="0.00158" ixy="0.0" ixz="0.0" iyy="0.00124" iyz="-0.0001" izz="0.00115"/>
    </inertial>
  </link>
  <!-- Link 2 -->
  <link name="rf_upperleg">
    <inertial>
      <origin rpy="0.0 0.0 0.0" xyz="0.195737 0.0 0.003607"/>
      <mass value="0.66"/>
      <inertia ixx="0.00181" ixy="0.0" ixz="0.00037" iyy="0.0075" iyz="0.0" izz="0.00781"/>
    </inertial>
  </link>
  <!-- Link 3 -->
  <link name="rf_lowerleg">
    <inertial>
      <origin rpy="0.0 0.0 0.0" xyz="0.088807 0.0 0.0207547"/>
      <mass value="0.7218395407433646"/>
      <inertia ixx="0.003849" ixy="0.0" ixz="0.0" iyy="0.00235" iyz="0.0" izz="0.00472"/>
    </inertial>
  </link>
  <!-- Link foot -->
  <link name="rf_foot">
    <!--                        <inertial>
                          <origin xyz="0 0 0" rpy="0 0 0"/>
                          <mass value="1"/>
                          <inertia ixx="1.0" ixy="0.0" ixz="0.0" iyy="1.0" iyz="0.0" izz="1.0"/>
                        </inertial>-->
  </link>
  <!--//////////////////////////////////////////////////////////////////////////////////-->
  <!-- Hip assembly -->
  <!-- Joints -->
  <!-- Joint 1 -->
  <joint name="lh_haa_joint" type="revolute">
    <origin rpy="3.1415926 0 0" xyz="-0.32729 0.16972 -0.02722"/>
    <parent link="trunk"/>
    <child link="lh_hipassembly"/>
    <axis xyz="0 0 1"/>
    <limit effort="25.0" lower="-2.35619" upper="2.35619" velocity="3.0"/>
    <dynamics damping="0.1" friction="0"/>
    <!--safety_controller k_position="50" k_velocity="10"
                      soft_lower_limit="${(1-knee_bent_backward)*(hfe_min)*PI/180 + (knee_bent_backward)*(-hfe_max)*PI/180}"
                      soft_upper_limit="${(1-knee_bent_backward)*(hfe_max)*PI/180 + (knee_bent_backward)*(-hfe_min)*PI/180}"/-->
  </joint>
  <!-- Joint 2 -->
  <joint name="lh_hfe_joint" type="revolute">
    <origin rpy="1.570794 1.570795 0" xyz="0.0 -0.03931 0.05871"/>
    <parent link="lh_hipassembly"/>
    <child link="lh_upperleg"/>
    <axis xyz="0 0 1"/>
    <limit effort="25.0" lower="-2.95" upper="2.95" velocity="3.0"/>
    <dynamics damping="0.1" friction="0"/>
    <!--safety_controller k_position="50" k_velocity="10"
                      soft_lower_limit="${(1-knee_bent_backward)*(hfe_min)*PI/180 + (knee_bent_backward)*(-hfe_max)*PI/180}"
                      soft_upper_limit="${(1-knee_bent_backward)*(hfe_max)*PI/180 + (knee_bent_backward)*(-hfe_min)*PI/180}"/-->
  </joint>
  <!-- Joint 3 -->
  <joint name="lh_kfe_joint" type="revolute">
    <origin rpy="0.0 0.0 3.141591" xyz="0.22 0.0 0.0409"/>
    <parent link="lh_upperleg"/>
    <child link="lh_lowerleg"/>
    <axis xyz="0 0 1"/>
    <limit effort="25.0" lower="-2.95" upper="2.95" velocity="3.0"/>
    <dynamics damping="0.1" friction="0"/>
    <!--safety_controller k_position="50" k_velocity="10"
                      soft_lower_limit="${(1-knee_bent_backward)*(hfe_min)*PI/180 + (knee_bent_backward)*(-hfe_max)*PI/180}"
                      soft_upper_limit="${(1-knee_bent_backward)*(hfe_max)*PI/180 + (knee_bent_backward)*(-hfe_min)*PI/180}"/-->
  </joint>
  <!-- Joint foot -->
  <joint name="lh_foot_joint" type="fixed">
    <origin rpy="-3.141592 0.0 0.0" xyz="0.28 -0.00028 0.00674"/>
    <parent link="lh_lowerleg"/>
    <child link="lh_foot"/>
  </joint>
  <!-- Links of Peripheral Legs-->
  <!-- Link 1 -->
  <link name="lh_hipassembly">
    <inertial>
      <origin rpy="0.0 0.0 0.0" xyz="0.0 -0.0014 0.05421"/>
      <mass value="0.547"/>
      <inertia ixx="0.00158" ixy="0.0" ixz="0.0" iyy="0.00124" iyz="-0.0001" izz="0.00115"/>
    </inertial>
  </link>
  <!-- Link 2 -->
  <link name="lh_upperleg">
    <inertial>
      <origin rpy="0.0 0.0 0.0" xyz="0.195737 0.0 0.003607"/>
      <mass value="0.66"/>
      <inertia ixx="0.00181" ixy="0.0" ixz="0.00037" iyy="0.0075" iyz="0.0" izz="0.00781"/>
    </inertial>
  </link>
  <!-- Link 3 -->
  <link name="lh_lowerleg">
    <inertial>
      <origin rpy="0.0 0.0 0.0" xyz="0.088807 0.0 0.020754"/>
      <mass value="0.721839"/>
      <inertia ixx="0.003849" ixy="0.0" ixz="0.0" iyy="0.00235" iyz="0.0" izz="0.00472"/>
    </inertial>
  </link>
  <!-- Link foot -->
  <link name="lh_foot">
    <!--                        <inertial>
                          <origin xyz="0 0 0" rpy="0 0 0"/>
                          <mass value="1"/>
                          <inertia ixx="1.0" ixy="0.0" ixz="0.0" iyy="1.0" iyz="0.0" izz="1.0"/>
                        </inertial>-->
  </link>
  <!--//////////////////////////////////////////////////////////////////////////////////-->
  <!-- Hip assembly -->
  <!-- Joints -->
  <!-- Joint 1 -->
  <joint name="rh_haa_joint" type="revolute">
    <origin rpy="0 3.141592 0" xyz="-0.32729 -0.16972 -0.02722"/>
    <parent link="trunk"/>
    <child link="rh_hipassembly"/>
    <axis xyz="0 0 1"/>
    <limit effort="25.0" lower="-2.35619" upper="2.35619" velocity="3.0"/>
    <dynamics damping="0.1" friction="0"/>
    <!--safety_controller k_position="50" k_velocity="10"
                      soft_lower_limit="${(1-knee_bent_backward)*(hfe_min)*PI/180 + (knee_bent_backward)*(-hfe_max)*PI/180}"
                      soft_upper_limit="${(1-knee_bent_backward)*(hfe_max)*PI/180 + (knee_bent_backward)*(-hfe_min)*PI/180}"/-->
  </joint>
  <!-- Joint 2 -->
  <joint name="rh_hfe_joint" type="revolute">
    <origin rpy="1.570794 1.570795 0" xyz="0.0 -0.03931 0.05871"/>
    <parent link="rh_hipassembly"/>
    <child link="rh_upperleg"/>
    <axis xyz="0 0 1"/>
    <limit effort="25.0" lower="-2.95" upper="2.95" velocity="3.0"/>
    <dynamics damping="0.1" friction="0"/>
    <!--safety_controller k_position="50" k_velocity="10"
                      soft_lower_limit="${(1-knee_bent_backward)*(hfe_min)*PI/180 + (knee_bent_backward)*(-hfe_max)*PI/180}"
                      soft_upper_limit="${(1-knee_bent_backward)*(hfe_max)*PI/180 + (knee_bent_backward)*(-hfe_min)*PI/180}"/-->
  </joint>
  <!-- Joint 3 -->
  <joint name="rh_kfe_joint" type="revolute">
    <origin rpy="0.0 0.0 3.141591" xyz="0.22 0.0 0.0409"/>
    <parent link="rh_upperleg"/>
    <child link="rh_lowerleg"/>
    <axis xyz="0 0 1"/>
    <limit effort="25.0" lower="-2.95" upper="2.95" velocity="3.0"/>
    <dynamics damping="0.1" friction="0"/>
    <!--safety_controller k_position="50" k_velocity="10"
                      soft_lower_limit="${(1-knee_bent_backward)*(hfe_min)*PI/180 + (knee_bent_backward)*(-hfe_max)*PI/180}"
                      soft_upper_limit="${(1-knee_bent_backward)*(hfe_max)*PI/180 + (knee_bent_backward)*(-hfe_min)*PI/180}"/-->
  </joint>
  <!-- Joint foot -->
  <joint name="rh_foot_joint" type="fixed">
    <origin rpy="-3.141592 0.0 0.0" xyz="0.28 -0.00028 0.00674"/>
    <parent link="rh_lowerleg"/>
    <child link="rh_foot"/>
  </joint>
  <!-- Links of Peripheral Legs-->
  <!-- Link 1 -->
  <link name="rh_hipassembly">
    <inertial>
      <origin rpy="0.0 0.0 0.0" xyz="0.0 -0.0014 0.05421"/>
      <mass value="0.547"/>
      <inertia ixx="0.00158" ixy="0.0" ixz="0.0" iyy="0.00124" iyz="-0.0001" izz="0.00115"/>
    </inertial>
  </link>
  <!-- Link 2 -->
  <link name="rh_upperleg">
    <inertial>
      <origin rpy="0.0 0.0 0.0" xyz="0.195737 0.0 0.003607"/>
      <mass value="0.66"/>
      <inertia ixx="0.00181" ixy="0.0" ixz="0.00037" iyy="0.0075" iyz="0.0" izz="0.00781"/>
    </inertial>
  </link>
  <!-- Link 3 -->
  <link name="rh_lowerleg">
    <inertial>
      <origin rpy="0.0 0.0 0.0" xyz="0.0888074 0.0 0.0207547"/>
      <mass value="0.7218395407433646"/>
      <inertia ixx="0.0038499" ixy="0.0" ixz="0.0" iyy="0.00235" iyz="0.0" izz="0.00472"/>
    </inertial>
  </link>
  <!-- Link foot -->
  <link name="rh_foot">
    <!--                        <inertial>
                          <origin xyz="0 0 0" rpy="0 0 0"/>
                          <mass value="1"/>
                          <inertia ixx="1.0" ixy="0.0" ixz="0.0" iyy="1.0" iyz="0.0" izz="1.0"/>
                        </inertial>-->
  </link>
  <!--//////////////////////////////////////////////////////////////////////////////////-->
  <!-- Hip assembly -->
  <!--//////////////////////////////////////////////////////////////////////////////////-->
  <!-- Joints -->
  <!-- Joint 1 -->
  <joint name="lc_haa_joint" type="revolute">
    <origin rpy="3.141592 0 0" xyz="-0.06672 0.24531 0.01452"/>
    <parent link="trunk"/>
    <child link="lc_hipassembly"/>
    <axis xyz="0 0 1"/>
    <limit effort="25.0" lower="-2.35619" upper="2.35619" velocity="3.0"/>
    <dynamics damping="0.1" friction="0"/>
    <!--safety_controller k_position="50" k_velocity="10"
                      soft_lower_limit="${(1-knee_bent_backward)*(hfe_min)*PI/180 + (knee_bent_backward)*(-hfe_max)*PI/180}"
                      soft_upper_limit="${(1-knee_bent_backward)*(hfe_max)*PI/180 + (knee_bent_backward)*(-hfe_min)*PI/180}"/-->
  </joint>
  <!-- Joint 2 -->
  <joint name="lc_hfe_joint" type="revolute">
    <origin rpy="1.570794 1.570795 0" xyz="0.0 -0.03938 0.0586"/>
    <parent link="lc_hipassembly"/>
    <child link="lc_upperleg"/>
    <axis xyz="0 0 1"/>
    <limit effort="25.0" lower="-2.95" upper="2.95" velocity="3.0"/>
    <dynamics damping="0.1" friction="0"/>
    <!--safety_controller k_position="50" k_velocity="10"
                      soft_lower_limit="${(1-knee_bent_backward)*(hfe_min)*PI/180 + (knee_bent_backward)*(-hfe_max)*PI/180}"
                      soft_upper_limit="${(1-knee_bent_backward)*(hfe_max)*PI/180 + (knee_bent_backward)*(-hfe_min)*PI/180}"/-->
  </joint>
  <!-- Joint 3 -->
  <joint name="lc_kfe_joint" type="revolute">
    <origin rpy="0 0 3.141592" xyz="0.2 0.0 0.04087"/>
    <parent link="lc_upperleg"/>
    <child link="lc_lowerleg"/>
    <axis xyz="0 0 1"/>
    <limit effort="25.0" lower="-2.95" upper="2.95" velocity="3.0"/>
    <dynamics damping="0.1" friction="0"/>
    <!--safety_controller k_position="50" k_velocity="10"
                      soft_lower_limit="${(1-knee_bent_backward)*(hfe_min)*PI/180 + (knee_bent_backward)*(-hfe_max)*PI/180}"
                      soft_upper_limit="${(1-knee_bent_backward)*(hfe_max)*PI/180 + (knee_bent_backward)*(-hfe_min)*PI/180}"/-->
  </joint>
  <!-- Joint foot -->
  <joint name="lc_foot_joint" type="fixed">
    <origin rpy="-3.141592 0 0" xyz="0.3 0.0 0.00723"/>
    <parent link="lc_lowerleg"/>
    <child link="lc_foot"/>
  </joint>
  <!-- Links of central Legs-->
  <!-- Link 1 -->
  <link name="lc_hipassembly">
    <inertial>
      <origin rpy="0.0 0.0 0.0" xyz="0.0 -0.0014 0.05421"/>
      <mass value="0.547"/>
      <inertia ixx="0.00158" ixy="0.0" ixz="0.0" iyy="0.00124" iyz="-0.0001" izz="0.00115"/>
    </inertial>
  </link>
  <!-- Link 2 -->
  <link name="lc_upperleg">
    <inertial>
      <origin rpy="0.0 0.0 0.0" xyz="0.179272 0.0 0.003467"/>
      <mass value="0.66"/>
      <inertia ixx="0.00166" ixy="0.0" ixz="0.00034" iyy="0.0064" iyz="0.0" izz="0.00657"/>
    </inertial>
  </link>
  <!-- Link 3 -->
  <link name="lc_lowerleg">
    <inertial>
      <origin rpy="0.0 0.0 0.0" xyz="0.0889605 0.0 0.0263546"/>
      <mass value="0.7208525181223551"/>
      <inertia ixx="0.003849" ixy="0.0" ixz="0.0" iyy="0.0023399999999999996" iyz="0.0" izz="0.00472"/>
    </inertial>
  </link>
  <!-- Link foot -->
  <link name="lc_foot">
    <!--                        <inertial>
                          <origin xyz="0 0 0" rpy="0 0 0"/>
                          <mass value="1"/>
                          <inertia ixx="1.0" ixy="0.0" ixz="0.0" iyy="1.0" iyz="0.0" izz="1.0"/>
                        </inertial>-->
  </link>
  <!-- Hip assembly -->
  <!--//////////////////////////////////////////////////////////////////////////////////-->
  <!-- Joints -->
  <!-- Joint 1 -->
  <joint name="rc_haa_joint" type="revolute">
    <origin rpy="0 3.141592 0" xyz="-0.06672 -0.24531 0.01452"/>
    <parent link="trunk"/>
    <child link="rc_hipassembly"/>
    <axis xyz="0 0 1"/>
    <limit effort="25.0" lower="-2.35619" upper="2.35619" velocity="3.0"/>
    <dynamics damping="0.1" friction="0"/>
    <!--safety_controller k_position="50" k_velocity="10"
                      soft_lower_limit="${(1-knee_bent_backward)*(hfe_min)*PI/180 + (knee_bent_backward)*(-hfe_max)*PI/180}"
                      soft_upper_limit="${(1-knee_bent_backward)*(hfe_max)*PI/180 + (knee_bent_backward)*(-hfe_min)*PI/180}"/-->
  </joint>
  <!-- Joint 2 -->
  <joint name="rc_hfe_joint" type="revolute">
    <origin rpy="1.570794 1.570795 0" xyz="0.0 -0.03938 0.0586"/>
    <parent link="rc_hipassembly"/>
    <child link="rc_upperleg"/>
    <axis xyz="0 0 1"/>
    <limit effort="25.0" lower="-2.95" upper="2.95" velocity="3.0"/>
    <dynamics damping="0.1" friction="0"/>
    <!--safety_controller k_position="50" k_velocity="10"
                      soft_lower_limit="${(1-knee_bent_backward)*(hfe_min)*PI/180 + (knee_bent_backward)*(-hfe_max)*PI/180}"
                      soft_upper_limit="${(1-knee_bent_backward)*(hfe_max)*PI/180 + (knee_bent_backward)*(-hfe_min)*PI/180}"/-->
  </joint>
  <!-- Joint 3 -->
  <joint name="rc_kfe_joint" type="revolute">
    <origin rpy="0 0 3.141592" xyz="0.2 0.0 0.04087"/>
    <parent link="rc_upperleg"/>
    <child link="rc_lowerleg"/>
    <axis xyz="0 0 1"/>
    <limit effort="25.0" lower="-2.95" upper="2.95" velocity="3.0"/>
    <dynamics damping="0.1" friction="0"/>
    <!--safety_controller k_position="50" k_velocity="10"
                      soft_lower_limit="${(1-knee_bent_backward)*(hfe_min)*PI/180 + (knee_bent_backward)*(-hfe_max)*PI/180}"
                      soft_upper_limit="${(1-knee_bent_backward)*(hfe_max)*PI/180 + (knee_bent_backward)*(-hfe_min)*PI/180}"/-->
  </joint>
  <!-- Joint foot -->
  <joint name="rc_foot_joint" type="fixed">
    <origin rpy="-3.141592 0 0" xyz="0.3 0.0 0.00723"/>
    <parent link="rc_lowerleg"/>
    <child link="rc_foot"/>
  </joint>
  <!-- Links of central Legs-->
  <!-- Link 1 -->
  <link name="rc_hipassembly">
    <inertial>
      <origin rpy="0.0 0.0 0.0" xyz="0.0 -0.0014 0.05421"/>
      <mass value="0.547"/>
      <inertia ixx="0.00158" ixy="0.0" ixz="0.0" iyy="0.00124" iyz="-0.0001" izz="0.00115"/>
    </inertial>
  </link>
  <!-- Link 2 -->
  <link name="rc_upperleg">
    <inertial>
      <origin rpy="0.0 0.0 0.0" xyz="0.179272 0.0 0.003467"/>
      <mass value="0.66"/>
      <inertia ixx="0.00166" ixy="0.0" ixz="0.00034" iyy="0.0064" iyz="0.0" izz="0.00657"/>
    </inertial>
  </link>
  <!-- Link 3 -->
  <link name="rc_lowerleg">
    <inertial>
      <origin rpy="0.0 0.0 0.0" xyz="0.088960 0.0 0.0263546"/>
      <mass value="0.7208525181223551"/>
      <inertia ixx="0.003849" ixy="0.0" ixz="0.0" iyy="0.002339" iyz="0.0" izz="0.00472"/>
    </inertial>
  </link>
  <!-- Link foot -->
  <link name="rc_foot">
    <!--                        <inertial>
                          <origin xyz="0 0 0" rpy="0 0 0"/>
                          <mass value="1"/>
                          <inertia ixx="1.0" ixy="0.0" ixz="0.0" iyy="1.0" iyz="0.0" izz="1.0"/>
                        </inertial>-->
  </link>
  <!-- Hip assembly -->
</robot>
