<?xml version="1.0" ?>
<!-- =================================================================================== -->
<!-- |    This document was autogenerated by xacro from aliengo.urdf.xacro             | -->
<!-- |    EDITING THIS FILE BY HAND IS NOT RECOMMENDED                                 | -->
<!-- =================================================================================== -->
<robot name="aliengo" xmlns:xacro="http://ros.org/wiki/xacro">
  <!-- <xacro:property name="trunk_mass" value="9.041"/> -->
  <!-- <xacro:property name="trunk_izz" value="0.17460442"/> -->
  <!-- <xacro:property name="trunk_iyz" value="0.000048356"/> -->
  <!-- <xacro:property name="hip_iyz" value="-0.00000175"/> -->
  <!-- <xacro:arg name="task_period" default="0.008"/> -->
  <!-- Links -->
  <!-- Trunk link -->
  <link name="trunk">
    <inertial>
      <origin xyz="0.008465 0.004045 -0.000763"/>
      <mass value="9.041"/>
      <inertia ixx="0.033260231" ixy="0.0" ixz="0.0" iyy="0.16117211" iyz="0.0" izz="0.17460442"/>
    </inertial>
  </link>
  <!-- Joints -->
  <!-- HAA joint -->
  <joint name="lf_haa_joint" type="revolute">
    <origin rpy="3.14159265359 1.57079632679 0" xyz="0.2399 0.051 0"/>
    <parent link="trunk"/>
    <child link="lf_hipassembly"/>
    <axis xyz="0 0 1"/>
    <dynamics damping="0.1" friction="0"/>
    <limit effort="44.0" lower="-1.2217304764" upper="1.2217304764" velocity="20.0"/>
    <safety_controller k_position="50" k_velocity="10" soft_lower_limit="-1.2217304764" soft_upper_limit="1.2217304764"/>
  </joint>
  <!-- HFE joint -->
  <joint name="lf_hfe_joint" type="revolute">
    <origin rpy="1.57079632679 0 0" xyz="0 -0.083 0"/>
    <parent link="lf_hipassembly"/>
    <child link="lf_upperleg"/>
    <axis xyz="0 0 1"/>
    <dynamics damping="0.1" friction="0"/>
    <limit effort="44.0" lower="-2.61799387799" upper="2.61799387799" velocity="20.0"/>
    <safety_controller k_position="50" k_velocity="10" soft_lower_limit="-2.61799387799" soft_upper_limit="2.61799387799"/>
  </joint>
  <!-- KFE joint -->
  <joint name="lf_kfe_joint" type="revolute">
    <origin rpy="0 0 0" xyz="0.25 0 0"/>
    <parent link="lf_upperleg"/>
    <child link="lf_lowerleg"/>
    <axis xyz="0 0 1"/>
    <dynamics damping="0.1" friction="0"/>
    <limit effort="55.0" lower="-2.77507351067" upper="-0.645771823238" velocity="16.0"/>
    <safety_controller k_position="50.0" k_velocity="10.0" soft_lower_limit="-2.77507351067" soft_upper_limit="-0.645771823238"/>
  </joint>
  <!-- Foot joint -->
  <joint name="lf_foot_joint" type="fixed">
    <origin rpy="1.57079632679 0 -1.57079632679" xyz="0.25 0 0"/>
    <parent link="lf_lowerleg"/>
    <child link="lf_foot"/>
  </joint>
  <!-- Links -->
  <!-- Hip assembly link -->
  <link name="lf_hipassembly">
    <inertial>
      <origin xyz="1.5e-05 -0.015144 0.022191"/>
      <mass value="1.993"/>
      <inertia ixx="0.005586944" ixy="-1.75e-06" ixz="-1.262e-06" iyy="0.004907517" iyz="-7.185e-05" izz="0.002903894"/>
    </inertial>
  </link>
  <!-- Upper leg link -->
  <link name="lf_upperleg">
    <inertial>
      <origin xyz="0.048199 0.005607 0.003877"/>
      <mass value="0.639"/>
      <inertia ixx="0.000369811" ixy="0.000491446" ixz="1.0086e-05" iyy="0.005666803" iyz="3.597e-06" izz="0.005847229"/>
    </inertial>
  </link>
  <!-- Lower leg link -->
  <link name="lf_lowerleg">
    <inertial>
      <origin xyz="0.142518 -0.002781 6.3e-05"/>
      <mass value="0.207"/>
      <inertia ixx="3.9188e-05" ixy="-8.7951e-05" ixz="-1.336e-06" iyy="0.006341369" iyz="-3e-09" izz="0.006355157"/>
    </inertial>
  </link>
  <!-- Foot link -->
  <link name="lf_foot">
  </link>
  <!-- Joints -->
  <!-- HAA joint -->
  <joint name="rf_haa_joint" type="revolute">
    <origin rpy="0 1.57079632679 0" xyz="0.2399 -0.051 0"/>
    <parent link="trunk"/>
    <child link="rf_hipassembly"/>
    <axis xyz="0 0 1"/>
    <dynamics damping="0.1" friction="0"/>
    <limit effort="44.0" lower="-1.2217304764" upper="1.2217304764" velocity="20.0"/>
    <safety_controller k_position="50" k_velocity="10" soft_lower_limit="-1.2217304764" soft_upper_limit="1.2217304764"/>
  </joint>
  <!-- HFE joint -->
  <joint name="rf_hfe_joint" type="revolute">
    <origin rpy="-1.57079632679 0 0" xyz="0 -0.083 0"/>
    <parent link="rf_hipassembly"/>
    <child link="rf_upperleg"/>
    <axis xyz="0 0 1"/>
    <dynamics damping="0.1" friction="0"/>
    <limit effort="44.0" lower="-2.61799387799" upper="2.61799387799" velocity="20.0"/>
    <safety_controller k_position="50" k_velocity="10" soft_lower_limit="-2.61799387799" soft_upper_limit="2.61799387799"/>
  </joint>
  <!-- KFE joint -->
  <joint name="rf_kfe_joint" type="revolute">
    <origin rpy="0 0 0" xyz="0.25 0 0"/>
    <parent link="rf_upperleg"/>
    <child link="rf_lowerleg"/>
    <axis xyz="0 0 1"/>
    <dynamics damping="0.1" friction="0"/>
    <limit effort="55.0" lower="-2.77507351067" upper="-0.645771823238" velocity="16.0"/>
    <safety_controller k_position="50.0" k_velocity="10.0" soft_lower_limit="-2.77507351067" soft_upper_limit="-0.645771823238"/>
  </joint>
  <!-- Foot joint -->
  <joint name="rf_foot_joint" type="fixed">
    <origin rpy="1.57079632679 0 -1.57079632679" xyz="0.25 0 0"/>
    <parent link="rf_lowerleg"/>
    <child link="rf_foot"/>
  </joint>
  <!-- Links -->
  <!-- Hip assembly link -->
  <link name="rf_hipassembly">
    <inertial>
      <origin xyz="1.5e-05 -0.015144 -0.022191"/>
      <mass value="1.993"/>
      <inertia ixx="0.005586944" ixy="-1.75e-06" ixz="-1.262e-06" iyy="0.004907517" iyz="-7.185e-05" izz="0.002903894"/>
    </inertial>
  </link>
  <!-- Upper leg link -->
  <link name="rf_upperleg">
    <inertial>
      <origin xyz="0.048199 0.005607 -0.003877"/>
      <mass value="0.639"/>
      <inertia ixx="0.000369811" ixy="0.000491446" ixz="-1.0086e-05" iyy="0.005666803" iyz="-3.597e-06" izz="0.005847229"/>
    </inertial>
  </link>
  <!-- Lower leg link -->
  <link name="rf_lowerleg">
    <inertial>
      <origin xyz="0.142518 -0.002781 6.3e-05"/>
      <mass value="0.207"/>
      <inertia ixx="3.9188e-05" ixy="-8.7951e-05" ixz="-1.336e-06" iyy="0.006341369" iyz="-3e-09" izz="0.006355157"/>
    </inertial>
  </link>
  <!-- Foot link -->
  <link name="rf_foot">
  </link>

  <!-- Joints -->
  <!-- HAA joint -->
  <joint name="lh_haa_joint" type="revolute">
    <origin rpy="3.14159265359 1.57079632679 0" xyz="-0.2399 0.051 0"/>
    <parent link="trunk"/>
    <child link="lh_hipassembly"/>
    <axis xyz="0 0 1"/>
    <dynamics damping="0.1" friction="0"/>
    <limit effort="44.0" lower="-1.2217304764" upper="1.2217304764" velocity="20.0"/>
    <safety_controller k_position="50" k_velocity="10" soft_lower_limit="-1.2217304764" soft_upper_limit="1.2217304764"/>
  </joint>
  <!-- HFE joint -->
  <joint name="lh_hfe_joint" type="revolute">
    <origin rpy="1.57079632679 0 0" xyz="0 -0.083 0"/>
    <parent link="lh_hipassembly"/>
    <child link="lh_upperleg"/>
    <axis xyz="0 0 1"/>
    <dynamics damping="0.1" friction="0"/>
    <limit effort="44.0" lower="-2.61799387799" upper="2.61799387799" velocity="20.0"/>
    <safety_controller k_position="50" k_velocity="10" soft_lower_limit="-2.61799387799" soft_upper_limit="2.61799387799"/>
  </joint>
  <!-- KFE joint -->
  <joint name="lh_kfe_joint" type="revolute">
    <origin rpy="0 0 0" xyz="0.25 0 0"/>
    <parent link="lh_upperleg"/>
    <child link="lh_lowerleg"/>
    <axis xyz="0 0 1"/>
    <dynamics damping="0.1" friction="0"/>
    <limit effort="55.0" lower="-2.77507351067" upper="-0.645771823238" velocity="16.0"/>
    <safety_controller k_position="50.0" k_velocity="10.0" soft_lower_limit="-2.77507351067" soft_upper_limit="-0.645771823238"/>
  </joint>
  <!-- Foot joint -->
  <joint name="lh_foot_joint" type="fixed">
    <origin rpy="1.57079632679 0 -1.57079632679" xyz="0.25 0 0"/>
    <parent link="lh_lowerleg"/>
    <child link="lh_foot"/>
  </joint>
  <!-- Links -->
  <!-- Hip assembly link -->
  <link name="lh_hipassembly">
    <inertial>
      <origin xyz="1.5e-05 -0.015144 0.022191"/>
      <mass value="1.993"/>
      <inertia ixx="0.005586944" ixy="-1.75e-06" ixz="-1.262e-06" iyy="0.004907517" iyz="-7.185e-05" izz="0.002903894"/>
    </inertial>
  </link>
  <!-- Upper leg link -->
  <link name="lh_upperleg">
    <inertial>
      <origin xyz="0.048199 0.005607 0.003877"/>
      <mass value="0.639"/>
      <inertia ixx="0.000369811" ixy="0.000491446" ixz="1.0086e-05" iyy="0.005666803" iyz="3.597e-06" izz="0.005847229"/>
    </inertial>
  </link>
  <!-- Lower leg link -->
  <link name="lh_lowerleg">
    <inertial>
      <origin xyz="0.142518 -0.002781 6.3e-05"/>
      <mass value="0.207"/>
      <inertia ixx="3.9188e-05" ixy="-8.7951e-05" ixz="-1.336e-06" iyy="0.006341369" iyz="-3e-09" izz="0.006355157"/>
    </inertial>
  </link>
  <!-- Foot link -->
  <link name="lh_foot">
  </link>
  <!-- Joints -->
  <!-- HAA joint -->
  <joint name="rh_haa_joint" type="revolute">
    <origin rpy="0 1.57079632679 0" xyz="-0.2399 -0.051 0"/>
    <parent link="trunk"/>
    <child link="rh_hipassembly"/>
    <axis xyz="0 0 1"/>
    <dynamics damping="0.1" friction="0"/>
    <limit effort="44.0" lower="-1.2217304764" upper="1.2217304764" velocity="20.0"/>
    <safety_controller k_position="50" k_velocity="10" soft_lower_limit="-1.2217304764" soft_upper_limit="1.2217304764"/>
  </joint>
  <!-- HFE joint -->
  <joint name="rh_hfe_joint" type="revolute">
    <origin rpy="-1.57079632679 0 0" xyz="0 -0.083 0"/>
    <parent link="rh_hipassembly"/>
    <child link="rh_upperleg"/>
    <axis xyz="0 0 1"/>
    <dynamics damping="0.1" friction="0"/>
    <limit effort="44.0" lower="-2.61799387799" upper="2.61799387799" velocity="20.0"/>
    <safety_controller k_position="50" k_velocity="10" soft_lower_limit="-2.61799387799" soft_upper_limit="2.61799387799"/>
  </joint>
  <!-- KFE joint -->
  <joint name="rh_kfe_joint" type="revolute">
    <origin rpy="0 0 0" xyz="0.25 0 0"/>
    <parent link="rh_upperleg"/>
    <child link="rh_lowerleg"/>
    <axis xyz="0 0 1"/>
    <dynamics damping="0.1" friction="0"/>
    <limit effort="55.0" lower="-2.77507351067" upper="-0.645771823238" velocity="16.0"/>
    <safety_controller k_position="50.0" k_velocity="10.0" soft_lower_limit="-2.77507351067" soft_upper_limit="-0.645771823238"/>
  </joint>
  <!-- Foot joint -->
  <joint name="rh_foot_joint" type="fixed">
    <origin rpy="1.57079632679 0 -1.57079632679" xyz="0.25 0 0"/>
    <parent link="rh_lowerleg"/>
    <child link="rh_foot"/>
  </joint>
  <!-- Links -->
  <!-- Hip assembly link -->
  <link name="rh_hipassembly">
    <inertial>
      <origin xyz="1.5e-05 -0.015144 -0.022191"/>
      <mass value="1.993"/>
      <inertia ixx="0.005586944" ixy="-1.75e-06" ixz="-1.262e-06" iyy="0.004907517" iyz="-7.185e-05" izz="0.002903894"/>
    </inertial>
  </link>
  <!-- Upper leg link -->
  <link name="rh_upperleg">
    <inertial>
      <origin xyz="0.048199 0.005607 -0.003877"/>
      <mass value="0.639"/>
      <inertia ixx="0.000369811" ixy="0.000491446" ixz="-1.0086e-05" iyy="0.005666803" iyz="-3.597e-06" izz="0.005847229"/>
    </inertial>
  </link>
  <!-- Lower leg link -->
  <link name="rh_lowerleg">
    <inertial>
      <origin xyz="0.142518 -0.002781 6.3e-05"/>
      <mass value="0.207"/>
      <inertia ixx="3.9188e-05" ixy="-8.7951e-05" ixz="-1.336e-06" iyy="0.006341369" iyz="-3e-09" izz="0.006355157"/>
    </inertial>
  </link>
  <!-- Foot link -->
  <link name="rh_foot">
  </link>
  <!--xacro:new_calibration_plate_xacro parent="lf_lowerleg"-->
  <!--origin xyz="0.393 -0.023 -0.1" rpy="${PI/2} 0 0"/-->
  <!--origin xyz="0.3588117 -0.0304911 -0.2088889" rpy="${PI/2} 0 -0.137881"/>
  </xacro:new_calibration_plate_xacro-->
</robot>
